<?xml version="1.0"?>
<robot xmlns:xacro="http://www.ros.org/wiki/xacro"  name="robot">
        
<xacro:include filename="inertial_macros.xacro"/>

    <material name="white">
        <color rgba="1 1 1 1"/>
    </material>

    <material name="black">
        <color rgba="0 0 0 1"/>
    </material>
    
    <material name="orange">
        <color rgba="1 0.3 0.1 1"/>
    </material>
    
    <material name="blue">
        <color rgba="0.2 0.2 1 1"/>
    </material>

    <material name="green">
        <color rgba="0 1 0 1"/>
    </material>

    <material name="red">
        <color rgba="0.8 0 0 1"/>
    </material>

    <material name="grey">
        <color rgba="0.2 0.2 0.2 1"/>
    </material>

<!-- BASE LINK -->
  <link name="base_link">
  </link>  
  
  <link name="base_footprint">
  </link>  

  <joint name="base_footprint_joint" type="fixed">
    <parent link="base_link"/>
    <child link="base_footprint"/>
    <origin xyz="0.0 0.0 0.0" rpy="0 0 0"/>
</joint>

<!-- CHASSIS LINK -->
 
  <link name="chassis">
      <visual>
        <geometry>
          <cylinder radius="0.135" length="0.078"/>
        </geometry>
        <material name="white"/>
      </visual>

      <collision>
        <geometry>
          <cylinder radius="0.135" length="0.078"/>
        </geometry>
      </collision>      
      <xacro:inertial_cylinder mass="0.4" length="0.078" radius="0.135">
        <origin xyz="0 0.018 0" rpy="0 0 0"/>
      </xacro:inertial_cylinder>  
  </link>

  <joint name="chassis_joint" type="fixed">
    <parent link="base_link"/>
    <child link="chassis"/>
    <origin xyz="0.0 0 0.02" rpy="0 0 0"/>
  </joint>
     
<!-- LEFT WHEEL LINK -->

  <link name="left_wheel">
      <visual>
        <geometry>
          <cylinder radius="0.04" length="0.008"/>
        </geometry>
        <material name="black"/>
      </visual>

      <collision>
        <geometry>
          <cylinder radius="0.04" length="0.008"/>
        </geometry>
      </collision>      
      <xacro:inertial_cylinder mass="0.1" length="0.008" radius="0.04">
        <origin xyz="0 0 0" rpy="0 0 0"/>
      </xacro:inertial_cylinder>  
  </link>

  <gazebo reference="left_wheel">
    <material>Gazebo/Black</material>
  </gazebo>

  <joint name="left_wheel_joint" type="continuous">
    <parent link="base_link"/>
    <child link="left_wheel"/>
    <origin xyz="0.0 0.078 0" rpy="-${pi/2} 0 0"/>
    <axis xyz="0 0 1"/>
</joint>
<!-- RIGHT WHEEL LINK -->


  <link name="right_wheel">
      <visual>
      
        <geometry>
          <cylinder radius="0.04" length="0.008"/>
        </geometry>
        <material name="blue"/>
      </visual>
      <collision>
      
        <geometry>
          <cylinder radius="0.04" length="0.008"/>
        </geometry>

      </collision>    
      <xacro:inertial_cylinder mass="0.05" length="0.008" radius="0.04">
        <origin xyz="0 0 0" rpy="0 0 0"/>
      </xacro:inertial_cylinder>    
  </link>
  <gazebo reference="right_wheel">
    <material>Gazebo/Black</material>

  </gazebo>
  <joint name="right_wheel_joint" type="continuous">
    <parent link="base_link"/>
    <child link="right_wheel"/>
    <origin xyz="0.0 -0.078 0.0" rpy="${pi/2} 0 0"/>
    <axis xyz="0 0 -1"/>
</joint>


<!-- CASTER WHEEL LINK-->

<link name="caster_wheel_front">

 <visual>
      
        <geometry>
          <sphere radius="0.019" />
        </geometry>
        <material name="blue"/>
      </visual>
      <collision>
      
        <geometry>
          <sphere radius="0.019" />
        </geometry>

      </collision>    
      <xacro:inertial_sphere mass="0.1" radius="0.019">
        <origin xyz="0 0 0" rpy="0 0 0"/>
      </xacro:inertial_sphere>    

</link> 
 
<joint name="caster_wheel_front_joint" type="fixed">
  <parent link="chassis"/>
  <child link="caster_wheel_front"/>
  <origin xyz="0.12 0 -0.039"/>
</joint>

<gazebo reference="caster_wheel_front">
  <material>Gazebo/Black</material>
  <mu1 value="0.001"/>
  <mu2 value="0.001"/>
</gazebo>



<link name="caster_wheel_rear">

 <visual>
      
        <geometry>
          <sphere radius="0.019" />
        </geometry>
        <material name="blue"/>
      </visual>
      <collision>
      
        <geometry>
          <sphere radius="0.019" />
        </geometry>

      </collision>    
      <xacro:inertial_sphere mass="0.1" radius="0.019">
        <origin xyz="0 0 0" rpy="0 0 0"/>
      </xacro:inertial_sphere>    

</link> 
 
<joint name="caster_wheel_rear_joint" type="fixed">
  <parent link="chassis"/>
  <child link="caster_wheel_rear"/>
  <origin xyz="-0.12 0 -0.039"/>
</joint>

<gazebo reference="caster_wheel_rear">
  <material>Gazebo/Black</material>
  <mu1 value="0.001"/>
  <mu2 value="0.001"/>
</gazebo>

</robot>
